Workbook
Name \0: #REF!
Name \0: #REF!
Name \0: #REF!
Name \0: #REF!
Name \0: #REF!
Name \a: #N/A
Name \b: #N/A
Name \c: #REF!
Name \c: #REF!
Name \c: #REF!
Name \c: #REF!
Name \c: #REF!
Name \D: [1]ANAL!#REF!
Name \D: [1]ANAL!#REF!
Name \D: [1]ANAL!#REF!
Name \D: [1]ANAL!#REF!
Name \D: [1]ANAL!#REF!
Name \d\srh.xls: [1]ANAL!#REF!
Name \d\srh.xls: [1]ANAL!#REF!
Name \d\srh.xls: [1]ANAL!#REF!
Name \d\srh.xls: [1]ANAL!#REF!
Name \d\srh.xls: [1]ANAL!#REF!
Name \H: '[2]#REF'!#REF!
Name \H: '[2]#REF'!#REF!
Name \o: '[3]Rate Analysis'!#REF!
Name \o: '[3]Rate Analysis'!#REF!
Name \p: #REF!
Name \p: #REF!
Name \p: #REF!
Name \p: #REF!
Name \p: #REF!
Name \s: #N/A
Name \z: #N/A
Name _______________________DAT13: #REF!
Name _______________________DAT13: #REF!
Name _______________________DAT14: #REF!
Name _______________________DAT14: #REF!
Name _______________________DAT15: '[4]SAP架設-2005.12.31'!#REF!
Name _______________________DAT15: '[4]SAP架設-2005.12.31'!#REF!
Name _______________________DAT17: #REF!
Name _______________________DAT17: #REF!
Name _______________________DAT17: #REF!
Name _______________________DAT17: #REF!
Name _______________________DAT17: #REF!
Name _______________________DAT19: #REF!
Name _______________________DAT19: #REF!
Name _______________________DAT19: #REF!
Name _______________________DAT19: #REF!
Name _______________________DAT19: #REF!
Name ______________________DAT13: #REF!
Name ______________________DAT13: #REF!
Name ______________________DAT13: #REF!
Name ______________________DAT13: #REF!
Name ______________________DAT13: #REF!
Name ______________________DAT14: #REF!
Name ______________________DAT14: #REF!
Name ______________________DAT15: '[4]SAP架設-2005.12.31'!#REF!
Name ______________________DAT15: '[4]SAP架設-2005.12.31'!#REF!
Name ______________________DAT17: #REF!
Name ______________________DAT17: #REF!

Sheet May-23 Plan- Completed
D1: 3 | E1: 20 | F1: 5 | G1: 6 | H1: 5 | I1: 10 | O1: 12 | P1: 0.5
A2: Concreting
A3: In-Situ | B3: SMS#4 Hot Metal Elevated Track ( In-Situ) | M3: Pre-cast | O3: SMS#4 Hot Metal Elevated Track (Pre-cast)
C4: Excavation | D4: PCC | E4: Foundation | F4: Step Footing | G4: Pier 1900 mm | H4: Pier 1600 mm | I4: Pier Cap | J4: Total | K4: Remarks | O4: Quantity | P4: Nos. | Q4: Remarks
A5: Priority Section-1 | B5: Nos. | C5: =C7+C9+C11+C13+C15+C17 -> 10 | D5: =D7+D9+D11+D13+D15+D17 -> 12 | E5: =E7+E9+E11+E13+E15+E17 -> 12 | F5: =F7+F9+F11+F13+F15+F17 -> 12 | G5: =G7+G9+G11+G13+G15+G17 -> 18 | H5: =H7+H9+H11+H13+H15+H17 -> 25 | I5: =I7+I9+I11+I13+I15+I17 -> 23 | M5: Track beam with nose | O5: =P5*$O$1 -> 1140 | P5: 95 | Q5: Concrete with OPC cement to be available at JSW batching Plant
B6: Qty | C6: =C8+C10+C12+C14+C16+C18 -> 0 | D6: =D8+D10+D12+D14+D16+D18 -> 36 | E6: =E8+E10+E12+E14+E16+E18 -> 240 | F6: =F8+F10+F12+F14+F16+F18 -> 60 | G6: =G8+G10+G12+G14+G16+G18 -> 108 | H6: =H8+H10+H12+H14+H16+H18 -> 125 | I6: =I8+I10+I12+I14+I16+I18 -> 355 | J6: =SUM(C6:I6) -> 924 | M6: Track beam without nose | O6: =P6*$O$1 -> 960 | P6: 80
A7: Part A | B7: Nos. | C7: 6 | D7: 6 | E7: 6 | F7: 6 | G7: 6 | H7: 14 | I7: 14 | M7: h-section beam | O7: =P7*$O$1 -> 336 | P7: 28
B8: Qty | D8: =D7*$D$1 -> 18 | E8: =E7*$E$1 -> 120 | F8: =F7*$F$1 -> 30 | G8: =G7*$G$1 -> 36 | H8: =H7*$H$1 -> 70 | I8: =I7*$I$1 -> 140 | J8: =SUM(C8:I8) -> 414 | M8: U-section beam | O8: =P8*$O$1 -> 336 | P8: 28
A9: Part B | B9: Nos. | C9: 4 | D9: 6 | E9: 6 | F9: 6 | G9: 6 | H9: 2 | M9: Pre-cast Slab | O9: =P9*P1 -> 38 | P9: 76
B10: Qty | D10: =D9*$D$1 -> 18 | E10: =E9*$E$1 -> 120 | F10: =F9*$F$1 -> 30 | G10: =G9*$G$1 -> 36 | H10: =H9*$H$1 -> 10 | I10: =I9*10 -> 0 | J10: =SUM(C10:I10) -> 214 | M10: Total: | O10: =SUM(O5:O9) -> 2810 | P10: =SUM(P5:P9) -> 307
A11: Part H | B11: Nos. | I11: 4 | U11: Month Plan | V11: Interim
B12: Qty | D12: =D11*$D$1 -> 0 | E12: =E11*$E$1 -> 0 | F12: =F11*$F$1 -> 0 | G12: =G11*$G$1 -> 0 | H12: =H11*$H$1 -> 0 | I12: =3*35+10 -> 115 | J12: =SUM(C12:I12) -> 115 | M12: All qty are in Cum | P12: Cast-in-situ | Q12: Pre-cast | R12: Total | T12: PCC | U12: =D32 -> 36 | V12: =U12*$P$43 -> 17.451423
A13: Part C | B13: Nos. | G13: 6 | H13: 9 | I13: 5 | O13: A | P13: =J8 -> 414 | Q13: =$O$10/11 -> 255.45455 | R13: =P13+Q13 -> 669.45455 | T13: RCC Foundation | U13: =E32 -> 240 | V13: =U13*$P$43 -> 116.34282
B14: Qty | D14: =D13*$D$1 -> 0 | E14: =E13*$E$1 -> 0 | F14: =F13*$F$1 -> 0 | G14: =G13*$G$1 -> 36 | H14: =H13*$H$1 -> 45 | I14: =5*20 -> 100 | J14: =SUM(C14:I14) -> 181 | O14: B | P14: =J10 -> 214 | Q14: =$O$10/11 -> 255.45455 | R14: =P14+Q14 -> 469.45455 | T14: Step Footing | U14: =F32 -> 60 | V14: =U14*$P$43 -> 29.085704
A15: Part I | B15: Nos. | O15: C | P15: =J14 -> 181 | Q15: =$O$10/11 -> 255.45455 | R15: =P15+Q15 -> 436.45455 | T15: Pier 1900 mm | U15: =G32 -> 132 | V15: =U15*$P$43 -> 63.988549
B16: Qty | D16: =D15*$D$1 -> 0 | E16: =E15*$E$1 -> 0 | F16: =F15*$F$1 -> 0 | G16: =G15*$G$1 -> 0 | H16: =H15*$H$1 -> 0 | I16: =I15*$I$1 -> 0 | J16: =SUM(C16:I16) -> 0 | O16: D | P16: =J18 -> 0 | Q16: =$O$10/11 -> 255.45455 | R16: =P16+Q16 -> 255.45455 | T16: Pier 1600 mm | U16: =H32 -> 500 | V16: =U16*$P$43 -> 242.38087
A17: Part D | B17: Nos. | O17: E | P17: =J22 -> 15 | Q17: =$O$10/11 -> 255.45455 | R17: =P17+Q17 -> 270.45455 | T17: Pier Cap | U17: =I32 -> 355 | V17: =U17*$P$43 -> 172.09042
B18: Qty | D18: =D17*$D$1 -> 0 | E18: =E17*$E$1 -> 0 | F18: =F17*$F$1 -> 0 | G18: =G17*$G$1 -> 0 | H18: =H17*$H$1 -> 0 | I18: =I17*20 -> 0 | J18: =SUM(C18:I18) -> 0 | O18: F | P18: =J24 -> 150 | Q18: =$O$10/11 -> 255.45455 | R18: =P18+Q18 -> 405.45455 | T18: Track Beam with Nose | U18: =O5 -> 1140 | V18: =U18*$P$43 -> 552.62838
A19: Priority Section-2 | B19: Nos. | C19: =C21+C23+C25+C27+C29 -> 0 | D19: =D21+D23+D25+D27+D29 -> 0 | E19: =E21+E23+E25+E27+E29 -> 0 | F19: =F21+F23+F25+F27+F29 -> 0 | G19: =G21+G23+G25+G27+G29 -> 4 | H19: =H21+H23+H25+H27+H29 -> 75 | I19: =I21+I23+I25+I27+I29 -> 0 | O19: G | P19: =J26 -> 150 | Q19: =$O$10/11 -> 255.45455 | R19: =P19+Q19 -> 405.45455 | T19: Track Beam without Nose | U19: =O6 -> 960 | V19: =U19*$P$43 -> 465.37127
B20: Qty | C20: =C22+C24+C26+C28+C30 -> 0 | D20: =D22+D24+D26+D28+D30 -> 0 | E20: =E22+E24+E26+E28+E30 -> 0 | F20: =F22+F24+F26+F28+F30 -> 0 | G20: =G22+G24+G26+G28+G30 -> 24 | H20: =H22+H24+H26+H28+H30 -> 375 | I20: =I22+I24+I26+I28+I30 -> 0 | J20: =SUM(C20:I20) -> 399 | O20: H | P20: =J12 -> 115 | Q20: =$O$10/11 -> 255.45455 | R20: =P20+Q20 -> 370.45455 | T20: H - Section Beam | U20: =O7 -> 336 | V20: =U20*$P$43 -> 162.87994
A21: Part E | B21: Nos. | H21: 3 | O21: I | P21: =J16 -> 0 | Q21: =$O$10/11 -> 255.45455 | R21: =P21+Q21 -> 255.45455 | T21: U - Section Beam | U21: =O8 -> 336 | V21: =U21*$P$43 -> 162.87994
B22: Qty | D22: =D21*$D$1 -> 0 | E22: =E21*$E$1 -> 0 | F22: =F21*$F$1 -> 0 | G22: =G21*$G$1 -> 0 | H22: =H21*$H$1 -> 15 | I22: =I21*$I$1 -> 0 | J22: =SUM(C22:I22) -> 15 | O22: J | P22: =J28 -> 60 | Q22: =$O$10/11 -> 255.45455 | R22: =P22+Q22 -> 315.45455 | T22: Pre-cast Slab | U22: =O9 -> 38 | V22: =U22*$P$43 -> 18.420946
A23: Part F | B23: Nos. | H23: 30 | O23: K | P23: =J30 -> 24 | Q23: =$O$10/11 -> 255.45455 | R23: =P23+Q23 -> 279.45455
B24: Qty | D24: =D23*$D$1 -> 0 | E24: =E23*$E$1 -> 0 | F24: =F23*$F$1 -> 0 | G24: =G23*$G$1 -> 0 | H24: =H23*$H$1 -> 150 | I24: =I23*$I$1 -> 0 | J24: =SUM(C24:I24) -> 150 | P24: =SUM(P13:P23) -> 1323 | Q24: =SUM(Q13:Q23) -> 2810 | R24: =SUM(R13:R23) -> 4133
A25: Part G | B25: Nos. | H25: 30
B26: Qty | D26: =D25*$D$1 -> 0 | E26: =E25*$E$1 -> 0 | F26: =F25*$F$1 -> 0 | G26: =G25*$G$1 -> 0 | H26: =H25*$H$1 -> 150 | I26: =I25*$I$1 -> 0 | J26: =SUM(C26:I26) -> 150
A27: Part J | B27: Nos. | H27: 12
B28: Qty | D28: =D27*$D$1 -> 0 | E28: =E27*$E$1 -> 0 | F28: =F27*$F$1 -> 0 | G28: =G27*$G$1 -> 0 | H28: =H27*$H$1 -> 60 | I28: =I27*$I$1 -> 0 | J28: =SUM(C28:I28) -> 60
A29: Part K | B29: Nos. | G29: 4 | K29: Clearence to be given by 10th Feb 2023 from JSW.
B30: Qty | D30: =D29*$D$1 -> 0 | E30: =E29*$E$1 -> 0 | F30: =F29*$F$1 -> 0 | G30: =G29*$G$1 -> 24 | H30: =H29*$H$1 -> 0 | I30: =I29*$I$1 -> 0 | J30: =SUM(C30:I30) -> 24
A31: Total | B31: Nos. | C31: =C5+C19 -> 10 | D31: =D5+D19 -> 12 | E31: =E5+E19 -> 12 | F31: =F5+F19 -> 12 | G31: =G5+G19 -> 22 | H31: =H5+H19 -> 100 | I31: =I5+I19 -> 23
B32: Qty | C32: =C6+C20 -> 0 | D32: =D6+D20 -> 36 | E32: =E6+E20 -> 240 | F32: =F6+F20 -> 60 | G32: =G6+G20 -> 132 | H32: =H6+H20 -> 500 | I32: =I6+I20 -> 355 | J32: =SUM(C32:I32) -> 1323
J36: Pre-cast | K36: Week-wise Planned
K37: Week 1 (1 to 8) | M37: =$O$10*N37 -> 673.13965 | N37: 0.23955148
K38: Week 2 (9 to 16) | M38: =$O$10*N38 -> 703.21611 | N38: 0.25025484
K39: Week 3 (17 to 24) | M39: =$O$10*N39 -> 703.21611 | N39: 0.25025484
K40: Week 4 (25 to 31) | M40: =$O$10*N40 -> 730.42813 | N40: 0.25993884
K41: Total | M41: =SUM(M37:M40) -> 2810
J42: Cast-in-situ | K42: Week-wise Planned
K43: Week 1 (1 to 8) | M43: =$J$32*N43 -> 277.69706 | N43: 0.20989952 | O43: =(N37+N43)/2 -> 0.2247255 | P43: =O43+O44 -> 0.48476174
...

Sheet Jul-23 Plan - Old 
D1: 3 | E1: 20 | F1: 5 | G1: 6 | H1: 5 | I1: 10 | J1: 35 | O1: 12 | P1: 0.5
A2: Concreting
A3: In-Situ | B3: SMS#4 Hot Metal Elevated Track ( In-Situ) | M3: Pre-cast | O3: SMS#4 Hot Metal Elevated Track (Pre-cast)
C4: Excavation | D4: PCC | E4: Foundation | F4: Step Footing | G4: Pier 1900 mm | H4: Pier 1600 mm | I4: Pier Cap | J4: Total | K4: Remarks | O4: Quantity | P4: Nos. | Q4: Remarks
A5: Priority Section-1 | B5: Nos. | C5: =C7+C9+C11+C13+C15+C17 -> 0 | D5: =D7+D9+D11+D13+D15+D17 -> 0 | E5: =E7+E9+E11+E13+E15+E17 -> 0 | F5: =F7+F9+F11+F13+F15+F17 -> 0 | G5: =G7+G9+G11+G13+G15+G17 -> 0 | H5: =H7+H9+H11+H13+H15+H17 -> 0 | I5: =I7+I9+I11+I13+I15+I17 -> 0 | M5: Track beam with nose | O5: =P5*$O$1 -> 720 | P5: 60 | Q5: Concrete with OPC cement to be available at JSW batching Plant
B6: Qty | C6: =C8+C10+C12+C14+C16+C18 -> 0 | D6: =D8+D10+D12+D14+D16+D18 -> 0 | E6: =E8+E10+E12+E14+E16+E18 -> 0 | F6: =F8+F10+F12+F14+F16+F18 -> 0 | G6: =G8+G10+G12+G14+G16+G18 -> 0 | H6: =H8+H10+H12+H14+H16+H18 -> 0 | I6: =I8+I10+I12+I14+I16+I18 -> 0 | J6: =SUM(C6:I6) -> 0 | M6: Track beam without nose | O6: =P6*$O$1 -> 720 | P6: 60
A7: Part A | B7: Nos. | M7: h-section beam | O7: =P7*$O$1 -> 300 | P7: 25
B8: Qty | D8: =D7*$D$1 -> 0 | E8: =E7*$E$1 -> 0 | F8: =F7*$F$1 -> 0 | G8: =G7*$G$1 -> 0 | H8: =H7*$H$1 -> 0 | I8: =I7*$I$1 -> 0 | J8: =SUM(C8:I8) -> 0 | M8: U-section beam | O8: =P8*$O$1 -> 300 | P8: 25
A9: Part B | B9: Nos. | M9: Pre-cast Slab | O9: =P9*P1 -> 30 | P9: 60
B10: Qty | D10: =D9*$D$1 -> 0 | E10: =E9*$E$1 -> 0 | F10: =F9*$F$1 -> 0 | G10: =G9*$G$1 -> 0 | H10: =H9*$H$1 -> 0 | I10: =I9*20 -> 0 | J10: =SUM(C10:I10) -> 0 | M10: Total: | O10: =SUM(O5:O9) -> 2070 | P10: =SUM(P5:P9) -> 230 | Z10: Pre-cast | AC10: Cast Insitu | AD10: Total | AE10: UOM | AF10: Track beam with nose | AG10: Track beam without nose | AH10: h-section beam | AI10: U-section beam | AJ10: Pre-cast Slab | AK10: Total
A11: Part H | B11: Nos. | U11: Month Plan | V11: Interim | AA11: Qty | AB11: Cum | AC11: Cum | AD11: Cum | AE11: Nos. | AF11: ='Plan- Rohan'!U80 -> 60 | AG11: ='Plan- Rohan'!V80 -> 60 | AH11: ='Plan- Rohan'!W80 -> 20 | AI11: ='Plan- Rohan'!X80 -> 20 | AJ11: ='Plan- Rohan'!Y80 -> 60 | AK11: ='Plan- Rohan'!Z80 -> 220
B12: Qty | D12: =D11*$D$1 -> 0 | E12: =E11*$E$1 -> 0 | F12: =F11*$F$1 -> 0 | G12: =G11*$G$1 -> 0 | H12: =H11*$H$1 -> 0 | I12: =I11*J1 -> 0 | J12: =SUM(C12:I12) -> 0 | M12: All qty are in Cum | P12: Cast-in-situ | Q12: Pre-cast | R12: Total | T12: PCC | U12: =D32 -> 159 | V12: =U12*$P$43 -> 77.077116 | Z12: A | AA12: ='Plan- Rohan'!Z56 -> 0 | AB12: ='Plan- Rohan'!Z57 -> 0 | AC12: 0 | AD12: =AB12+AC12 -> 0 | AE12: Qty | AF12: ='Plan- Rohan'!U81 -> 720 | AG12: ='Plan- Rohan'!V81 -> 720 | AH12: ='Plan- Rohan'!W81 -> 240 | AI12: ='Plan- Rohan'!X81 -> 240 | AJ12: ='Plan- Rohan'!Y81 -> 30 | AK12: ='Plan- Rohan'!Z81 -> 1950
A13: Part C | B13: Nos. | O13: A | P13: =J8 -> 0 | Q13: =$O$10/11 -> 188.18182 | R13: =P13+Q13 -> 188.18182 | T13: RCC Foundation | U13: =E32 -> 740 | V13: =U13*$P$43 -> 358.72369 | Z13: B | AA13: ='Plan- Rohan'!Z58 -> 0 | AB13: ='Plan- Rohan'!Z59 -> 0 | AC13: 0 | AD13: =AB13+AC13 -> 0
B14: Qty | D14: =D13*$D$1 -> 0 | E14: =E13*$E$1 -> 0 | F14: =F13*$F$1 -> 0 | G14: =G13*$G$1 -> 0 | H14: =H13*$H$1 -> 0 | I14: =I13*$H$1 -> 0 | J14: =SUM(C14:I14) -> 0 | O14: B | P14: =J10 -> 0 | Q14: =$O$10/11 -> 188.18182 | R14: =P14+Q14 -> 188.18182 | T14: Step Footing | U14: =F32 -> 185 | V14: =U14*$P$43 -> 89.680922 | Z14: C | AA14: ='Plan- Rohan'!Z62 -> 16 | AB14: ='Plan- Rohan'!Z63 -> 192 | AC14: 0 | AD14: =AB14+AC14 -> 192
A15: Part I | B15: Nos. | O15: C | P15: =J14 -> 0 | Q15: =$O$10/11 -> 188.18182 | R15: =P15+Q15 -> 188.18182 | T15: Pier 1900 mm | U15: =G32 -> 120 | V15: =U15*$P$43 -> 58.171409 | Z15: D | AA15: ='Plan- Rohan'!Z66 -> 0 | AB15: ='Plan- Rohan'!Z67 -> 0 | AC15: 0 | AD15: =AB15+AC15 -> 0
B16: Qty | D16: =D15*$D$1 -> 0 | E16: =E15*$E$1 -> 0 | F16: =F15*$F$1 -> 0 | G16: =G15*$G$1 -> 0 | H16: =H15*$H$1 -> 0 | I16: =I15*$I$1 -> 0 | J16: =SUM(C16:I16) -> 0 | O16: D | P16: =J18 -> 0 | Q16: =$O$10/11 -> 188.18182 | R16: =P16+Q16 -> 188.18182 | T16: Pier 1600 mm | U16: =H32 -> 850 | V16: =U16*$P$43 -> 412.04748 | Z16: E | AA16: ='Plan- Rohan'!Z70 -> 0 | AB16: ='Plan- Rohan'!Z71 -> 0 | AC16: 476 | AD16: =AB16+AC16 -> 476
A17: Part D | B17: Nos. | O17: E | P17: =J22 -> 476 | Q17: =$O$10/11 -> 188.18182 | R17: =P17+Q17 -> 664.18182 | T17: Pier Cap | U17: =I32 -> 300 | V17: =U17*$P$43 -> 145.42852 | Z17: F | AA17: ='Plan- Rohan'!Z72 -> 0 | AB17: ='Plan- Rohan'!Z73 -> 0 | AC17: 225 | AD17: =AB17+AC17 -> 225
B18: Qty | D18: =D17*$D$1 -> 0 | E18: =E17*$E$1 -> 0 | F18: =F17*$F$1 -> 0 | G18: =G17*$G$1 -> 0 | H18: =H17*$H$1 -> 0 | I18: =I17*20 -> 0 | J18: =SUM(C18:I18) -> 0 | O18: F | P18: =J24 -> 225 | Q18: =$O$10/11 -> 188.18182 | R18: =P18+Q18 -> 413.18182 | T18: Track Beam with Nose | U18: =O5 -> 720 | V18: =U18*$P$43 -> 349.02845 | Z18: G | AA18: ='Plan- Rohan'!Z74 -> 159 | AB18: ='Plan- Rohan'!Z75 -> 1218 | AC18: 328 | AD18: =AB18+AC18 -> 1546
A19: Priority Section-2 | B19: Nos. | C19: =C21+C23+C25+C27+C29 -> 53 | D19: =D21+D23+D25+D27+D29 -> 53 | E19: =E21+E23+E25+E27+E29 -> 37 | F19: =F21+F23+F25+F27+F29 -> 37 | G19: =G21+G23+G25+G27+G29 -> 20 | H19: =H21+H23+H25+H27+H29 -> 170 | I19: =I21+I23+I25+I27+I29 -> 20 | O19: G | P19: =J26 -> 328 | Q19: =$O$10/11 -> 188.18182 | R19: =P19+Q19 -> 516.18182 | T19: Track Beam without Nose | U19: =O6 -> 720 | V19: =U19*$P$43 -> 349.02845 | Z19: H | AA19: ='Plan- Rohan'!Z60 -> 5 | AB19: ='Plan- Rohan'!Z61 -> 60 | AC19: 0 | AD19: =AB19+AC19 -> 60
B20: Qty | C20: =C22+C24+C26+C28+C30 -> 0 | D20: =D22+D24+D26+D28+D30 -> 159 | E20: =E22+E24+E26+E28+E30 -> 740 | F20: =F22+F24+F26+F28+F30 -> 185 | G20: =G22+G24+G26+G28+G30 -> 120 | H20: =H22+H24+H26+H28+H30 -> 850 | I20: =I22+I24+I26+I28+I30 -> 300 | J20: =SUM(C20:I20) -> 2354 | O20: H | P20: =J12 -> 0 | Q20: =$O$10/11 -> 188.18182 | R20: =P20+Q20 -> 188.18182 | T20: H - Section Beam | U20: =O7 -> 300 | V20: =U20*$P$43 -> 145.42852 | Z20: I | AA20: ='Plan- Rohan'!Z64 -> 40 | AB20: ='Plan- Rohan'!Z65 -> 480 | AC20: 0 | AD20: =AB20+AC20 -> 480
A21: Part E | B21: Nos. | C21: 17 | D21: 17 | E21: 17 | F21: 17 | O21: I | P21: =J16 -> 0 | Q21: =$O$10/11 -> 188.18182 | R21: =P21+Q21 -> 188.18182 | T21: U - Section Beam | U21: =O8 -> 300 | V21: =U21*$P$43 -> 145.42852 | Z21: J | AA21: ='Plan- Rohan'!Z76 -> 0 | AB21: ='Plan- Rohan'!Z77 -> 0 | AC21: 375 | AD21: =AB21+AC21 -> 375
B22: Qty | D22: =D21*$D$1 -> 51 | E22: =E21*$E$1 -> 340 | F22: =F21*$F$1 -> 85 | G22: =G21*$G$1 -> 0 | H22: =H21*$H$1 -> 0 | I22: =I21*$I$1 -> 0 | J22: =SUM(C22:I22) -> 476 | O22: J | P22: =J28 -> 395 | Q22: =$O$10/11 -> 188.18182 | R22: =P22+Q22 -> 583.18182 | T22: Pre-cast Slab | U22: =O9 -> 30 | V22: =U22*$P$43 -> 14.542852 | Z22: K | AA22: ='Plan- Rohan'!Z78 -> 0 | AB22: ='Plan- Rohan'!Z79 -> 0 | AC22: 930 | AD22: =AB22+AC22 -> 930
A23: Part F | B23: Nos. | H23: 45 | O23: K | P23: =J30 -> 930 | Q23: =$O$10/11 -> 188.18182 | R23: =P23+Q23 -> 1118.1818 | AA23: =SUM(AA12:AA22) -> 220 | AB23: =SUM(AB12:AB22) -> 1950 | AC23: =SUM(AC12:AC22) -> 2334 | AD23: =SUM(AD12:AD22) -> 4284
B24: Qty | D24: =D23*$D$1 -> 0 | E24: =E23*$E$1 -> 0 | F24: =F23*$F$1 -> 0 | G24: =G23*$G$1 -> 0 | H24: =H23*$H$1 -> 225 | I24: 0 | J24: =SUM(C24:I24) -> 225 | P24: =SUM(P13:P23) -> 2354 | Q24: =SUM(Q13:Q23) -> 2070 | R24: =SUM(R13:R23) -> 4424
A25: Part G | B25: Nos. | C25: 16 | D25: 16 | I25: 18
B26: Qty | D26: =D25*$D$1 -> 48 | E26: =E25*$E$1 -> 0 | F26: =F25*$F$1 -> 0 | G26: =G25*$G$1 -> 0 | H26: =H25*$H$1 -> 0 | I26: =8*10+10*20 -> 280 | J26: =SUM(C26:I26) -> 328
A27: Part J | B27: Nos. | H27: 75 | I27: 2
B28: Qty | D28: =D27*$D$1 -> 0 | E28: =E27*$E$1 -> 0 | F28: =F27*$F$1 -> 0 | G28: =G27*$G$1 -> 0 | H28: =H27*$H$1 -> 375 | I28: =I27*$I$1 -> 20 | J28: =SUM(C28:I28) -> 395
A29: Part K | B29: Nos. | C29: 20 | D29: 20 | E29: 20 | F29: 20 | G29: 20 | H29: 50 | K29: Clearence to be given by 10th Feb 2023 from JSW.
B30: Qty | D30: =D29*$D$1 -> 60 | E30: =E29*$E$1 -> 400 | F30: =F29*$F$1 -> 100 | G30: =G29*$G$1 -> 120 | H30: =H29*$H$1 -> 250 | I30: =I29*$I$1 -> 0 | J30: =SUM(C30:I30) -> 930
A31: Total | B31: Nos. | C31: =C5+C19 -> 53 | D31: =D5+D19 -> 53 | E31: =E5+E19 -> 37 | F31: =F5+F19 -> 37 | G31: =G5+G19 -> 20 | H31: =H5+H19 -> 170 | I31: =I5+I19 -> 20
B32: Qty | C32: =C6+C20 -> 0 | D32: =D6+D20 -> 159 | E32: =E6+E20 -> 740 | F32: =F6+F20 -> 185 | G32: =G6+G20 -> 120 | H32: =H6+H20 -> 850 | I32: =I6+I20 -> 300 | J32: =SUM(C32:I32) -> 2354
J36: Pre-cast | K36: Week-wise Planned
K37: Week 1 (1 to 8) | M37: =$O$10*N37 -> 495.87156 | N37: 0.23955148
K38: Week 2 (9 to 16) | M38: =$O$10*N38 -> 518.02752 | N38: 0.25025484
K39: Week 3 (17 to 24) | M39: =$O$10*N39 -> 518.02752 | N39: 0.25025484
K40: Week 4 (25 to 31) | M40: =$O$10*N40 -> 538.07339 | N40: 0.25993884
K41: Total | M41: =SUM(M37:M40) -> 2070
J42: Cast-in-situ | K42: Week-wise Planned
K43: Week 1 (1 to 8) | M43: =$J$32*N43 -> 494.10346 | N43: 0.20989952 | O43: =(N37+N43)/2 -> 0.2247255 | P43: =O43+O44 -> 0.48476174
...

Sheet Aug-23 Plan -old
D1: 3 | E1: 20 | F1: 5 | G1: 6 | H1: 5 | I1: 10 | J1: 35 | O1: 12 | P1: 0.5
A2: Concreting
A3: In-Situ | B3: SMS#4 Hot Metal Elevated Track ( In-Situ) | M3: Pre-cast | O3: SMS#4 Hot Metal Elevated Track (Pre-cast)
C4: Excavation | D4: PCC | E4: Foundation | F4: Step Footing | G4: Pier 1900 mm | H4: Pier 1600 mm | I4: Pier Cap | J4: Total | K4: Remarks | O4: Quantity | P4: Nos. | Q4: Remarks
A5: Priority Section-1 | B5: Nos. | C5: =C7+C9+C11+C13+C15+C17 -> 0 | D5: =D7+D9+D11+D13+D15+D17 -> 0 | E5: =E7+E9+E11+E13+E15+E17 -> 0 | F5: =F7+F9+F11+F13+F15+F17 -> 0 | G5: =G7+G9+G11+G13+G15+G17 -> 0 | H5: =H7+H9+H11+H13+H15+H17 -> 0 | I5: =I7+I9+I11+I13+I15+I17 -> 0 | M5: Track beam with nose | O5: =P5*$O$1 -> 720 | P5: 60 | Q5: Concrete with OPC cement to be available at JSW batching Plant
B6: Qty | C6: =C8+C10+C12+C14+C16+C18 -> 0 | D6: =D8+D10+D12+D14+D16+D18 -> 0 | E6: =E8+E10+E12+E14+E16+E18 -> 0 | F6: =F8+F10+F12+F14+F16+F18 -> 0 | G6: =G8+G10+G12+G14+G16+G18 -> 0 | H6: =H8+H10+H12+H14+H16+H18 -> 0 | I6: =I8+I10+I12+I14+I16+I18 -> 0 | J6: =SUM(C6:I6) -> 0 | M6: Track beam without nose | O6: =P6*$O$1 -> 720 | P6: 60
A7: Part A | B7: Nos. | M7: h-section beam | O7: =P7*$O$1 -> 240 | P7: 20
B8: Qty | D8: =D7*$D$1 -> 0 | E8: =E7*$E$1 -> 0 | F8: =F7*$F$1 -> 0 | G8: =G7*$G$1 -> 0 | H8: =H7*$H$1 -> 0 | I8: =I7*$I$1 -> 0 | J8: =SUM(C8:I8) -> 0 | M8: U-section beam | O8: =P8*$O$1 -> 240 | P8: 20
A9: Part B | B9: Nos. | M9: Pre-cast Slab | O9: =P9*P1 -> 30 | P9: 60
B10: Qty | D10: =D9*$D$1 -> 0 | E10: =E9*$E$1 -> 0 | F10: =F9*$F$1 -> 0 | G10: =G9*$G$1 -> 0 | H10: =H9*$H$1 -> 0 | I10: =I9*20 -> 0 | J10: =SUM(C10:I10) -> 0 | M10: Total: | O10: =SUM(O5:O9) -> 1950 | P10: =SUM(P5:P9) -> 220 | Z10: Pre-cast | AC10: Cast Insitu | AD10: Total | AE10: UOM | AF10: Track beam with nose | AG10: Track beam without nose | AH10: h-section beam | AI10: U-section beam | AJ10: Pre-cast Slab | AK10: Total
A11: Part H | B11: Nos. | U11: Month Plan | V11: Interim | AA11: Qty | AB11: Cum | AC11: Cum | AD11: Cum | AE11: Nos. | AF11: ='Plan- Rohan'!U80 -> 60 | AG11: ='Plan- Rohan'!V80 -> 60 | AH11: ='Plan- Rohan'!W80 -> 20 | AI11: ='Plan- Rohan'!X80 -> 20 | AJ11: ='Plan- Rohan'!Y80 -> 60 | AK11: ='Plan- Rohan'!Z80 -> 220
B12: Qty | D12: =D11*$D$1 -> 0 | E12: =E11*$E$1 -> 0 | F12: =F11*$F$1 -> 0 | G12: =G11*$G$1 -> 0 | H12: =H11*$H$1 -> 0 | I12: =I11*J1 -> 0 | J12: =SUM(C12:I12) -> 0 | M12: All qty are in Cum | P12: Cast-in-situ | Q12: Pre-cast | R12: Total | T12: PCC | U12: =D32 -> 0 | V12: =U12*$P$47 -> 0 | Z12: A | AA12: ='Plan- Rohan'!Z56 -> 0 | AB12: ='Plan- Rohan'!Z57 -> 0 | AC12: ='Plan- Rohan'!J8 -> 204 | AD12: =AB12+AC12 -> 204 | AE12: Qty | AF12: ='Plan- Rohan'!U81 -> 720 | AG12: ='Plan- Rohan'!V81 -> 720 | AH12: ='Plan- Rohan'!W81 -> 240 | AI12: ='Plan- Rohan'!X81 -> 240 | AJ12: ='Plan- Rohan'!Y81 -> 30 | AK12: ='Plan- Rohan'!Z81 -> 1950
A13: Part C | B13: Nos. | O13: A | P13: =J8 -> 0 | Q13: ='Precast- Segment Casting plan '!U14 -> 0 | R13: =P13+Q13 -> 0 | T13: RCC Foundation | U13: =E32 -> 0 | V13: =U13*$P$47 -> 0 | Z13: B | AA13: ='Plan- Rohan'!Z58 -> 0 | AB13: ='Plan- Rohan'!Z59 -> 0 | AC13: ='Plan- Rohan'!J10 -> 358 | AD13: =AB13+AC13 -> 358
B14: Qty | D14: =D13*$D$1 -> 0 | E14: =E13*$E$1 -> 0 | F14: =F13*$F$1 -> 0 | G14: =G13*$G$1 -> 0 | H14: =H13*$H$1 -> 0 | I14: =I13*$H$1 -> 0 | J14: =SUM(C14:I14) -> 0 | O14: B | P14: =J10 -> 0 | Q14: ='Precast- Segment Casting plan '!U15 -> 12 | R14: =P14+Q14 -> 12 | T14: Step Footing | U14: =F32 -> 50 | V14: =U14*$P$47 -> 24.238087 | Z14: C | AA14: ='Plan- Rohan'!Z62 -> 16 | AB14: ='Plan- Rohan'!Z63 -> 192 | AC14: ='Plan- Rohan'!J14 -> 0 | AD14: =AB14+AC14 -> 192
A15: Part I | B15: Nos. | O15: C | P15: =J14 -> 0 | Q15: ='Precast- Segment Casting plan '!U16 -> 96 | R15: =P15+Q15 -> 96 | T15: Pier 1900 mm | U15: =G32 -> 72 | V15: =U15*$P$47 -> 34.902845 | Z15: D | AA15: ='Plan- Rohan'!Z66 -> 0 | AB15: ='Plan- Rohan'!Z67 -> 0 | AC15: ='Plan- Rohan'!J18 -> 0 | AD15: =AB15+AC15 -> 0
B16: Qty | D16: =D15*$D$1 -> 0 | E16: =E15*$E$1 -> 0 | F16: =F15*$F$1 -> 0 | G16: =G15*$G$1 -> 0 | H16: =H15*$H$1 -> 0 | I16: =I15*$I$1 -> 0 | J16: =SUM(C16:I16) -> 0 | O16: D | P16: =J18 -> 0 | Q16: ='Precast- Segment Casting plan '!U17 -> 0 | R16: =P16+Q16 -> 0 | T16: Pier 1600 mm | U16: =H32 -> 600 | V16: =U16*$P$47 -> 290.85704 | Z16: E | AA16: ='Plan- Rohan'!Z70 -> 0 | AB16: ='Plan- Rohan'!Z71 -> 0 | AC16: ='Plan- Rohan'!J20 -> 0 | AD16: =AB16+AC16 -> 0
A17: Part D | B17: Nos. | O17: E | P17: =J22 -> 0 | Q17: ='Precast- Segment Casting plan '!U18 -> 48 | R17: =P17+Q17 -> 48 | T17: Pier Cap | U17: =I32 -> 604 | V17: =U17*$P$47 -> 292.79609 | Z17: F | AA17: ='Plan- Rohan'!Z72 -> 0 | AB17: ='Plan- Rohan'!Z73 -> 0 | AC17: ='Plan- Rohan'!J22 -> 150 | AD17: =AB17+AC17 -> 150
B18: Qty | D18: =D17*$D$1 -> 0 | E18: =E17*$E$1 -> 0 | F18: =F17*$F$1 -> 0 | G18: =G17*$G$1 -> 0 | H18: =H17*$H$1 -> 0 | I18: =I17*20 -> 0 | J18: =SUM(C18:I18) -> 0 | O18: F | P18: =J24 -> 440 | Q18: ='Precast- Segment Casting plan '!U19 -> 0 | R18: =P18+Q18 -> 440 | T18: Track Beam with Nose | U18: =O5 -> 720 | V18: =U18*$P$47 -> 349.02845 | Z18: G | AA18: ='Plan- Rohan'!Z74 -> 159 | AB18: ='Plan- Rohan'!Z75 -> 1218 | AC18: ='Plan- Rohan'!J24 -> 452 | AD18: =AB18+AC18 -> 1670
A19: Priority Section-2 | B19: Nos. | C19: =C21+C23+C25+C27+C29 -> 0 | D19: =D21+D23+D25+D27+D29 -> 0 | E19: =E21+E23+E25+E27+E29 -> 0 | F19: =F21+F23+F25+F27+F29 -> 10 | G19: =G21+G23+G25+G27+G29 -> 12 | H19: =H21+H23+H25+H27+H29 -> 120 | I19: =I21+I23+I25+I27+I29 -> 25 | O19: G | P19: =J26 -> 156 | Q19: ='Precast- Segment Casting plan '!U20 -> 286 | R19: =P19+Q19 -> 442 | T19: Track Beam without Nose | U19: =O6 -> 720 | V19: =U19*$P$47 -> 349.02845 | Z19: H | AA19: ='Plan- Rohan'!Z60 -> 5 | AB19: ='Plan- Rohan'!Z61 -> 60 | AC19: ='Plan- Rohan'!J12 -> 68 | AD19: =AB19+AC19 -> 128
B20: Qty | C20: =C22+C24+C26+C28+C30 -> 0 | D20: =D22+D24+D26+D28+D30 -> 0 | E20: =E22+E24+E26+E28+E30 -> 0 | F20: =F22+F24+F26+F28+F30 -> 50 | G20: =G22+G24+G26+G28+G30 -> 72 | H20: =H22+H24+H26+H28+H30 -> 600 | I20: =I22+I24+I26+I28+I30 -> 604 | J20: =SUM(C20:I20) -> 1326 | O20: H | P20: =J12 -> 0 | Q20: ='Precast- Segment Casting plan '!U21 -> 96 | R20: =P20+Q20 -> 96 | T20: H - Section Beam | U20: =O7 -> 240 | V20: =U20*$P$47 -> 116.34282 | Z20: I | AA20: ='Plan- Rohan'!Z64 -> 40 | AB20: ='Plan- Rohan'!Z65 -> 480 | AC20: ='Plan- Rohan'!J16 -> 0 | AD20: =AB20+AC20 -> 480
A21: Part E | B21: Nos. | O21: I | P21: =J16 -> 0 | Q21: ='Precast- Segment Casting plan '!U22 -> 12 | R21: =P21+Q21 -> 12 | T21: U - Section Beam | U21: =O8 -> 240 | V21: =U21*$P$47 -> 116.34282 | Z21: J | AA21: ='Plan- Rohan'!Z76 -> 0 | AB21: ='Plan- Rohan'!Z77 -> 0 | AC21: ='Plan- Rohan'!J26 -> 278 | AD21: =AB21+AC21 -> 278
B22: Qty | D22: =D21*$D$1 -> 0 | E22: =E21*$E$1 -> 0 | F22: =F21*$F$1 -> 0 | G22: =G21*$G$1 -> 0 | H22: =H21*$H$1 -> 0 | I22: =I21*$I$1 -> 0 | J22: =SUM(C22:I22) -> 0 | O22: J | P22: =J28 -> 268 | Q22: ='Precast- Segment Casting plan '!U23 -> 696 | R22: =P22+Q22 -> 964 | T22: Pre-cast Slab | U22: =O9 -> 30 | V22: =U22*$P$47 -> 14.542852 | Z22: K | AA22: ='Plan- Rohan'!Z78 -> 0 | AB22: ='Plan- Rohan'!Z79 -> 0 | AC22: ='Plan- Rohan'!J28 -> 594 | AD22: =AB22+AC22 -> 594
A23: Part F | B23: Nos. | H23: 20 | I23: 13 | O23: K | P23: =J30 -> 462 | Q23: ='Precast- Segment Casting plan '!U24 -> 334 | R23: =P23+Q23 -> 796 | T23: Abutment wall- PART-A | U23: =J33 -> 280 | V23: =U23*$P$47 -> 135.73329 | Z23: Abutment wall- PART-A | AC23: ='Plan- Rohan'!J29 -> 84 | AD23: =AB23+AC23 -> 84
B24: Qty | D24: =D23*$D$1 -> 0 | E24: =E23*$E$1 -> 0 | F24: =F23*$F$1 -> 0 | G24: =G23*$G$1 -> 0 | H24: =H23*$H$1 -> 100 | I24: =3*10+5*26+5*36 -> 340 | J24: =SUM(C24:I24) -> 440 | O24: Abutment wall- PART-A | P24: 280 | R24: =P24+Q24 -> 280 | T24: Abutment wall- PART-D | Z24: Abutment wall- PART-D | AD24: =AB24+AC24 -> 0
A25: Part G | B25: Nos. | I25: 6 | O25: Abutment wall- PART-D | P25: 0 | R25: =P25+Q25 -> 0 | T25: Cast In-situ slab- 1- PART-G | Z25: Cast In-situ slab- 1- PART-G | AD25: =AB25+AC25 -> 0
B26: Qty | D26: =D25*$D$1 -> 0 | E26: =E25*$E$1 -> 0 | F26: =F25*$F$1 -> 0 | G26: =G25*$G$1 -> 0 | H26: =H25*$H$1 -> 0 | I26: =I25*26 -> 156 | J26: =SUM(C26:I26) -> 156 | O26: Cast In-situ slab- 1- PART-G | P26: 0 | R26: =P26+Q26 -> 0 | T26: Cast In-situ slab- 2- PART-G | Z26: Cast In-situ slab- 2- PART-G | AD26: =AB26+AC26 -> 0
A27: Part J | B27: Nos. | H27: 32 | I27: 6 | O27: Cast In-situ slab- 2- PART-G | P27: 0 | R27: =P27+Q27 -> 0 | T27: Cast In-situ slab- PART-C | Z27: Cast In-situ slab- PART-C | AD27: =AB27+AC27 -> 0
B28: Qty | D28: =D27*$D$1 -> 0 | E28: =E27*$E$1 -> 0 | F28: =F27*$F$1 -> 0 | G28: =G27*$G$1 -> 0 | H28: =H27*$H$1 -> 160 | I28: =3*10+3*26 -> 108 | J28: =SUM(C28:I28) -> 268 | O28: Cast In-situ slab- PART-C | P28: 0 | R28: =P28+Q28 -> 0 | AA28: =SUM(AA12:AA27) -> 220 | AB28: =SUM(AB12:AB27) -> 1950 | AC28: =SUM(AC12:AC27) -> 2188 | AD28: =SUM(AD12:AD27) -> 4138
A29: Part K | B29: Nos. | F29: 10 | G29: 12 | H29: =(24*5)-H27-H23 -> 68 | P29: =SUM(P13:P28) -> 1606 | Q29: =SUM(Q13:Q28) -> 1580 | R29: =SUM(R13:R28) -> 3186
B30: Qty | D30: =D29*$D$1 -> 0 | E30: =E29*$E$1 -> 0 | F30: =F29*$F$1 -> 50 | G30: =G29*$G$1 -> 72 | H30: =H29*$H$1 -> 340 | I30: =I29*$I$1 -> 0 | J30: =SUM(C30:I30) -> 462
A31: Total | B31: Nos. | C31: =C5+C19 -> 0 | D31: =D5+D19 -> 0 | E31: =E5+E19 -> 0 | F31: =F5+F19 -> 10 | G31: =G5+G19 -> 12 | H31: =H5+H19 -> 120 | I31: =I5+I19 -> 25
B32: Qty | C32: =C6+C20 -> 0 | D32: =D6+D20 -> 0 | E32: =E6+E20 -> 0 | F32: =F6+F20 -> 50 | G32: =G6+G20 -> 72 | H32: =H6+H20 -> 600 | I32: =I6+I20 -> 604 | J32: =SUM(C32:I32) -> 1326
A33: Abutment wall- PART-A | D33: 25 | E33: 255 | J33: =SUM(C33:I33) -> 280
A34: Abutment wall- PART-D
A35: Cast In-situ slab- 1- PART-G
A36: Cast In-situ slab- 2- PART-G
A37: Cast In-situ slab- PART-C
A38: Cast Insitu | J38: =SUM(C38:I38) -> 0
J39: =SUM(J32:J38) -> 1606
J40: Pre-cast | K40: Week-wise Planned
...

Sheet Sep-23 Plan-Old
D1: 3 | E1: 20 | F1: 5 | G1: 6 | H1: 5 | I1: 10 | J1: 35 | O1: 12 | P1: 0.5
A2: Concreting
A3: In-Situ | B3: SMS#4 Hot Metal Elevated Track ( In-Situ) | M3: Pre-cast | O3: SMS#4 Hot Metal Elevated Track (Pre-cast)
C4: Excavation | D4: PCC | E4: Foundation | F4: Step Footing | G4: Pier 1900 mm | H4: Pier 1600 mm | I4: Pier Cap | J4: Total | K4: Remarks | O4: Quantity | P4: Nos. | Q4: Remarks
A5: Priority Section-1 | B5: Nos. | C5: =C7+C9+C11+C13+C15+C17 -> 22 | D5: =D7+D9+D11+D13+D15+D17 -> 24 | E5: =E7+E9+E11+E13+E15+E17 -> 18 | F5: =F7+F9+F11+F13+F15+F17 -> 18 | G5: =G7+G9+G11+G13+G15+G17 -> 18 | H5: =H7+H9+H11+H13+H15+H17 -> 0 | I5: =I7+I9+I11+I13+I15+I17 -> 0 | M5: Track beam with nose | O5: =P5*$O$1 -> 720 | P5: 60 | Q5: Concrete with OPC cement to be available at JSW batching Plant
B6: Qty | C6: =C8+C10+C12+C14+C16+C18 -> 0 | D6: =D8+D10+D12+D14+D16+D18 -> 72 | E6: =E8+E10+E12+E14+E16+E18 -> 360 | F6: =F8+F10+F12+F14+F16+F18 -> 90 | G6: =G8+G10+G12+G14+G16+G18 -> 108 | H6: =H8+H10+H12+H14+H16+H18 -> 0 | I6: =I8+I10+I12+I14+I16+I18 -> 0 | J6: =SUM(C6:I6) -> 630 | M6: Track beam without nose | O6: =P6*$O$1 -> 720 | P6: 60
A7: Part A | B7: Nos. | C7: 6 | D7: 6 | E7: 6 | F7: 6 | G7: 6 | M7: h-section beam | O7: =P7*$O$1 -> 240 | P7: 20
B8: Qty | D8: =D7*$D$1 -> 18 | E8: =E7*$E$1 -> 120 | F8: =F7*$F$1 -> 30 | G8: =G7*$G$1 -> 36 | H8: =H7*$H$1 -> 0 | I8: =I7*$I$1 -> 0 | J8: =SUM(D8:I8) -> 204 | M8: U-section beam | O8: =P8*$O$1 -> 240 | P8: 20
A9: Part B | B9: Nos. | C9: 16 | D9: 16 | E9: 10 | F9: 10 | G9: 10 | M9: Pre-cast Slab | O9: =P9*P1 -> 30 | P9: 60
B10: Qty | D10: =D9*$D$1 -> 48 | E10: =E9*$E$1 -> 200 | F10: =F9*$F$1 -> 50 | G10: =G9*$G$1 -> 60 | H10: =H9*$H$1 -> 0 | I10: =I9*20 -> 0 | J10: =SUM(D10:I10) -> 358 | M10: Total: | O10: =SUM(O5:O9) -> 1950 | P10: =SUM(P5:P9) -> 220 | Z10: Pre-cast | AC10: Cast Insitu | AD10: Total | AE10: UOM | AF10: Track beam with nose | AG10: Track beam without nose | AH10: h-section beam | AI10: U-section beam | AJ10: Pre-cast Slab | AK10: Total
A11: Part H | B11: Nos. | D11: 2 | E11: 2 | F11: 2 | G11: 2 | U11: Month Plan | V11: Interim | AA11: Qty | AB11: Cum | AC11: Cum | AD11: Cum | AE11: Nos. | AF11: ='Plan- Rohan'!U80 -> 60 | AG11: ='Plan- Rohan'!V80 -> 60 | AH11: ='Plan- Rohan'!W80 -> 20 | AI11: ='Plan- Rohan'!X80 -> 20 | AJ11: ='Plan- Rohan'!Y80 -> 60 | AK11: ='Plan- Rohan'!Z80 -> 220
B12: Qty | D12: =D11*$D$1 -> 6 | E12: =E11*$E$1 -> 40 | F12: =F11*$F$1 -> 10 | G12: =G11*$G$1 -> 12 | H12: =H11*$H$1 -> 0 | J12: =SUM(D12:I12) -> 68 | M12: All qty are in Cum | P12: Cast-in-situ | Q12: Pre-cast | R12: Total | T12: PCC | U12: =D32 -> 108 | V12: =U12*$P$47 -> 52.354268 | Z12: A | AA12: ='Plan- Rohan'!Z56 -> 0 | AB12: ='Plan- Rohan'!Z57 -> 0 | AC12: ='Plan- Rohan'!J8 -> 204 | AD12: =AB12+AC12 -> 204 | AE12: Qty | AF12: ='Plan- Rohan'!U81 -> 720 | AG12: ='Plan- Rohan'!V81 -> 720 | AH12: ='Plan- Rohan'!W81 -> 240 | AI12: ='Plan- Rohan'!X81 -> 240 | AJ12: ='Plan- Rohan'!Y81 -> 30 | AK12: ='Plan- Rohan'!Z81 -> 1950
A13: Part C | B13: Nos. | O13: A | P13: =J8 -> 204 | Q13: ='Precast- Segment Casting plan '!U14 -> 0 | R13: =P13+Q13 -> 204 | T13: RCC Foundation | U13: =E32 -> 600 | V13: =U13*$P$47 -> 290.85704 | Z13: B | AA13: ='Plan- Rohan'!Z58 -> 0 | AB13: ='Plan- Rohan'!Z59 -> 0 | AC13: ='Plan- Rohan'!J10 -> 358 | AD13: =AB13+AC13 -> 358
B14: Qty | D14: =D13*$D$1 -> 0 | E14: =E13*$E$1 -> 0 | F14: =F13*$F$1 -> 0 | G14: =G13*$G$1 -> 0 | H14: =H13*$H$1 -> 0 | J14: =SUM(D14:I14) -> 0 | O14: B | P14: =J10 -> 358 | Q14: ='Precast- Segment Casting plan '!U15 -> 12 | R14: =P14+Q14 -> 370 | T14: Step Footing | U14: =F32 -> 150 | V14: =U14*$P$47 -> 72.714261 | Z14: C | AA14: ='Plan- Rohan'!Z62 -> 16 | AB14: ='Plan- Rohan'!Z63 -> 192 | AC14: ='Plan- Rohan'!J14 -> 0 | AD14: =AB14+AC14 -> 192
A15: Part I | B15: Nos. | O15: C | P15: =J14 -> 0 | Q15: ='Precast- Segment Casting plan '!U16 -> 96 | R15: =P15+Q15 -> 96 | T15: Pier 1900 mm | U15: =G32 -> 240 | V15: =U15*$P$47 -> 116.34282 | Z15: D | AA15: ='Plan- Rohan'!Z66 -> 0 | AB15: ='Plan- Rohan'!Z67 -> 0 | AC15: ='Plan- Rohan'!J18 -> 0 | AD15: =AB15+AC15 -> 0
B16: Qty | D16: =D15*$D$1 -> 0 | E16: =E15*$E$1 -> 0 | F16: =F15*$F$1 -> 0 | G16: =G15*$G$1 -> 0 | H16: =H15*$H$1 -> 0 | I16: =I15*$I$1 -> 0 | J16: =SUM(D16:I16) -> 0 | O16: D | P16: =J18 -> 0 | Q16: ='Precast- Segment Casting plan '!U17 -> 0 | R16: =P16+Q16 -> 0 | T16: Pier 1600 mm | U16: =H32 -> 500 | V16: =U16*$P$47 -> 242.38087 | Z16: E | AA16: ='Plan- Rohan'!Z70 -> 0 | AB16: ='Plan- Rohan'!Z71 -> 0 | AC16: ='Plan- Rohan'!J20 -> 0 | AD16: =AB16+AC16 -> 0
A17: Part D | B17: Nos. | O17: E | P17: =J22 -> 0 | Q17: ='Precast- Segment Casting plan '!U18 -> 48 | R17: =P17+Q17 -> 48 | T17: Pier Cap | U17: =I32 -> 506 | V17: =U17*$P$47 -> 245.28944 | Z17: F | AA17: ='Plan- Rohan'!Z72 -> 0 | AB17: ='Plan- Rohan'!Z73 -> 0 | AC17: ='Plan- Rohan'!J22 -> 150 | AD17: =AB17+AC17 -> 150
B18: Qty | D18: =D17*$D$1 -> 0 | E18: =E17*$E$1 -> 0 | F18: =F17*$F$1 -> 0 | G18: =G17*$G$1 -> 0 | H18: =H17*$H$1 -> 0 | I18: =I17*20 -> 0 | J18: =SUM(D18:I18) -> 0 | O18: F | P18: =J24 -> 150 | Q18: ='Precast- Segment Casting plan '!U19 -> 0 | R18: =P18+Q18 -> 150 | T18: Track Beam with Nose | U18: =O5 -> 720 | V18: =U18*$P$47 -> 349.02845 | Z18: G | AA18: ='Plan- Rohan'!Z74 -> 159 | AB18: ='Plan- Rohan'!Z75 -> 1218 | AC18: ='Plan- Rohan'!J24 -> 452 | AD18: =AB18+AC18 -> 1670
A19: Priority Section-2 | B19: Nos. | C19: =C21+C23+C25+C27+C29 -> 0 | D19: =D21+D23+D25+D27+D29 -> 12 | E19: =E21+E23+E25+E27+E29 -> 12 | F19: =F21+F23+F25+F27+F29 -> 12 | G19: =G21+G23+G25+G27+G29 -> 22 | H19: =H21+H23+H25+H27+H29 -> 100 | I19: =I21+I23+I25+I27+I29 -> 20 | O19: G | P19: =J26 -> 452 | Q19: ='Precast- Segment Casting plan '!U20 -> 286 | R19: =P19+Q19 -> 738 | T19: Track Beam without Nose | U19: =O6 -> 720 | V19: =U19*$P$47 -> 349.02845 | Z19: H | AA19: ='Plan- Rohan'!Z60 -> 5 | AB19: ='Plan- Rohan'!Z61 -> 60 | AC19: ='Plan- Rohan'!J12 -> 68 | AD19: =AB19+AC19 -> 128
B20: Qty | C20: =C22+C24+C26+C28+C30 -> 0 | D20: =D22+D24+D26+D28+D30 -> 36 | E20: =E22+E24+E26+E28+E30 -> 240 | F20: =F22+F24+F26+F28+F30 -> 60 | G20: =G22+G24+G26+G28+G30 -> 132 | H20: =H22+H24+H26+H28+H30 -> 500 | I20: =I22+I24+I26+I28+I30 -> 506 | J20: =SUM(C20:I20) -> 1474 | O20: H | P20: =J12 -> 68 | Q20: ='Precast- Segment Casting plan '!U21 -> 96 | R20: =P20+Q20 -> 164 | T20: H - Section Beam | U20: =O7 -> 240 | V20: =U20*$P$47 -> 116.34282 | Z20: I | AA20: ='Plan- Rohan'!Z64 -> 40 | AB20: ='Plan- Rohan'!Z65 -> 480 | AC20: ='Plan- Rohan'!J16 -> 0 | AD20: =AB20+AC20 -> 480
A21: Part E | B21: Nos. | O21: I | P21: =J16 -> 0 | Q21: ='Precast- Segment Casting plan '!U22 -> 12 | R21: =P21+Q21 -> 12 | T21: U - Section Beam | U21: =O8 -> 240 | V21: =U21*$P$47 -> 116.34282 | Z21: J | AA21: ='Plan- Rohan'!Z76 -> 0 | AB21: ='Plan- Rohan'!Z77 -> 0 | AC21: ='Plan- Rohan'!J26 -> 278 | AD21: =AB21+AC21 -> 278
B22: Qty | D22: =D21*$D$1 -> 0 | E22: =E21*$E$1 -> 0 | F22: =F21*$F$1 -> 0 | G22: =G21*$G$1 -> 0 | H22: =H21*$H$1 -> 0 | I22: =I21*$I$1 -> 0 | J22: =SUM(D22:I22) -> 0 | O22: J | P22: =J28 -> 278 | Q22: ='Precast- Segment Casting plan '!U23 -> 696 | R22: =P22+Q22 -> 974 | T22: Pre-cast Slab | U22: =O9 -> 30 | V22: =U22*$P$47 -> 14.542852 | Z22: K | AA22: ='Plan- Rohan'!Z78 -> 0 | AB22: ='Plan- Rohan'!Z79 -> 0 | AC22: ='Plan- Rohan'!J28 -> 594 | AD22: =AB22+AC22 -> 594
A23: Part F | B23: Nos. | I23: 5 | O23: K | P23: =J30 -> 594 | Q23: ='Precast- Segment Casting plan '!U24 -> 334 | R23: =P23+Q23 -> 928 | T23: Abutment wall- PART-A | U23: =J33 -> 84 | V23: =U23*$P$47 -> 40.719986 | Z23: Abutment wall- PART-A | AC23: ='Plan- Rohan'!J29 -> 84 | AD23: =AB23+AC23 -> 84
B24: Qty | D24: =D23*$D$1 -> 0 | E24: =E23*$E$1 -> 0 | F24: =F23*$F$1 -> 0 | G24: =G23*$G$1 -> 0 | H24: =H23*$H$1 -> 0 | I24: =5*30 -> 150 | J24: =SUM(D24:I24) -> 150 | O24: Abutment wall- PART-A | P24: =J33 -> 84 | R24: =P24+Q24 -> 84 | T24: Abutment wall- PART-D | U24: =J34 -> 500 | Z24: Abutment wall- PART-D | AC24: ='Plan- Rohan'!J30 -> 500 | AD24: =AB24+AC24 -> 500
A25: Part G | B25: Nos. | D25: 6 | E25: 6 | F25: 6 | G25: 6 | I25: 12 | O25: Abutment wall- PART-D | P25: =J34 -> 500 | R25: =P25+Q25 -> 500 | T25: Cast In-situ slab- 1- PART-G | Z25: Cast In-situ slab- 1- PART-G | AD25: =AB25+AC25 -> 0
B26: Qty | D26: =D25*$D$1 -> 18 | E26: =E25*$E$1 -> 120 | F26: =F25*$F$1 -> 30 | G26: =G25*$G$1 -> 36 | H26: =H25*$H$1 -> 0 | I26: =8*26+4*10 -> 248 | J26: =SUM(D26:I26) -> 452 | O26: Cast In-situ slab- 1- PART-G | P26: 0 | R26: =P26+Q26 -> 0 | T26: Cast In-situ slab- 2- PART-G | Z26: Cast In-situ slab- 2- PART-G | AD26: =AB26+AC26 -> 0
A27: Part J | B27: Nos. | H27: 34 | I27: 3 | O27: Cast In-situ slab- 2- PART-G | P27: 0 | R27: =P27+Q27 -> 0 | T27: Cast In-situ slab- PART-C | Z27: Cast In-situ slab- PART-C | AD27: =AB27+AC27 -> 0
B28: Qty | D28: =D27*$D$1 -> 0 | E28: =E27*$E$1 -> 0 | F28: =F27*$F$1 -> 0 | G28: =G27*$G$1 -> 0 | H28: =H27*$H$1 -> 170 | I28: =I27*36 -> 108 | J28: =SUM(D28:I28) -> 278 | O28: Cast In-situ slab- PART-C | P28: 0 | R28: =P28+Q28 -> 0 | AA28: =SUM(AA12:AA27) -> 220 | AB28: =SUM(AB12:AB27) -> 1950 | AC28: =SUM(AC12:AC27) -> 2688 | AD28: =SUM(AD12:AD27) -> 4638
A29: Part K | B29: Nos. | D29: 6 | E29: 6 | F29: 6 | G29: 16 | H29: 66 | P29: =SUM(P13:P28) -> 2688 | Q29: =SUM(Q13:Q28) -> 1580 | R29: =SUM(R13:R28) -> 4268
B30: Qty | D30: =D29*$D$1 -> 18 | E30: =E29*$E$1 -> 120 | F30: =F29*$F$1 -> 30 | G30: =G29*$G$1 -> 96 | H30: =H29*$H$1 -> 330 | I30: =I29*$I$1 -> 0 | J30: =SUM(D30:I30) -> 594
A31: Total | B31: Nos. | C31: =C5+C19 -> 22 | D31: =D5+D19 -> 36 | E31: =E5+E19 -> 30 | F31: =F5+F19 -> 30 | G31: =G5+G19 -> 40 | H31: =H5+H19 -> 100 | I31: =I5+I19 -> 20
B32: Qty | C32: =C6+C20 -> 0 | D32: =D6+D20 -> 108 | E32: =E6+E20 -> 600 | F32: =F6+F20 -> 150 | G32: =G6+G20 -> 240 | H32: =H6+H20 -> 500 | I32: =I6+I20 -> 506 | J32: =SUM(C32:I32) -> 2104
A33: Abutment wall- PART-A | E33: 84 | J33: =SUM(C33:I33) -> 84
A34: Abutment wall- PART-D | E34: 500 | J34: =SUM(C34:I34) -> 500
A35: Cast In-situ slab- 1- PART-G | J35: =SUM(C35:I35) -> 0
A36: Cast In-situ slab- 2- PART-G | J36: =SUM(C36:I36) -> 0
A37: Cast In-situ slab- PART-C | J37: =SUM(C37:I37) -> 0
A38: Cast Insitu | J38: =SUM(C38:I38) -> 0
J39: =SUM(J32:J38) -> 2688
J40: Pre-cast | K40: Week-wise Planned
...

Sheet Nov-23 Plan (2)
D1: 3 | E1: 20 | F1: 5 | G1: 6 | H1: 5 | I1: 10 | J1: 35 | O1: 12 | P1: 0.5
A2: Concreting
A3: In-Situ | B3: SMS#4 Hot Metal Elevated Track ( In-Situ) | M3: Pre-cast | O3: SMS#4 Hot Metal Elevated Track (Pre-cast)
C4: Excavation | D4: PCC | E4: Foundation | F4: Step Footing | G4: Pier 1900 mm | H4: Pier 1600 mm | I4: Pier Cap | J4: Total | K4: Remarks | O4: Quantity | P4: Nos. | Q4: Remarks
A5: Priority Section-1 | B5: Nos. | C5: =C7+C9+C11+C13+C15+C17 -> 8 | D5: =D7+D9+D11+D13+D15+D17 -> 8 | E5: =E7+E9+E11+E13+E15+E17 -> 8 | F5: =F7+F9+F11+F13+F15+F17 -> 8 | G5: =G7+G9+G11+G13+G15+G17 -> 10 | H5: =H7+H9+H11+H13+H15+H17 -> 26 | I5: =I7+I9+I11+I13+I15+I17 -> 8 | M5: Track beam with nose | O5: =P5*$O$1 -> 996 | P5: ='[100]Precast- Segment Casting plan '!P29+'[100]Precast- Segment Casting plan '!P30 -> 83 | Q5: Concrete with OPC cement to be available at JSW batching Plant
B6: Qty | C6: =C8+C10+C12+C14+C16+C18 -> 0 | D6: =D8+D10+D12+D14+D16+D18 -> 24 | E6: =E8+E10+E12+E14+E16+E18 -> 160 | F6: =F8+F10+F12+F14+F16+F18 -> 40 | G6: =G8+G10+G12+G14+G16+G18 -> 60 | H6: =H8+H10+H12+H14+H16+H18 -> 130 | I6: =I8+I10+I12+I14+I16+I18 -> 160 | J6: =SUM(C6:I6) -> 574 | M6: Track beam without nose | O6: =P6*$O$1 -> 408 | P6: ='[100]Precast- Segment Casting plan '!P28 -> 34
A7: Part A | B7: Nos. | M7: h-section beam | O7: =P7*$O$1 -> 420 | P7: ='[100]Precast- Segment Casting plan '!P26 -> 35
B8: Qty | D8: =D7*$D$1 -> 0 | E8: =E7*$F$1 -> 0 | F8: =F7*$F$1 -> 0 | G8: =G7*$G$1 -> 0 | H8: =H7*$H$1 -> 0 | I8: =I7*$I$1 -> 0 | J8: =SUM(D8:I8) -> 0 | M8: U-section beam | O8: =P8*$O$1 -> 276 | P8: ='[100]Precast- Segment Casting plan '!P27 -> 23
A9: Part B | B9: Nos. | C9: 2 | D9: 2 | E9: 2 | F9: 2 | G9: 4 | H9: 14 | I9: 8 | M9: Pre-cast Slab | O9: =P9*P1 -> 20 | P9: ='[100]Precast- Segment Casting plan '!P31 -> 40
B10: Qty | D10: =D9*$D$1 -> 6 | E10: =E9*E1 -> 40 | F10: =F9*$F$1 -> 10 | G10: =G9*$G$1 -> 24 | H10: =H9*$H$1 -> 70 | I10: =I9*20 -> 160 | J10: =SUM(D10:I10) -> 310 | M10: Total: | O10: =SUM(O5:O9) -> 2120 | P10: =SUM(P5:P9) -> 215 | Z10: Pre-cast | AC10: Cast Insitu | AD10: Total | AE10: UOM | AF10: Track beam with nose | AG10: Track beam without nose | AH10: h-section beam | AI10: U-section beam | AJ10: Pre-cast Slab | AK10: Total
A11: Part H | B11: Nos. | C11: 2 | D11: 2 | E11: 2 | F11: 2 | G11: 2 | H11: 4 | U11: Month Plan | V11: Interim | AA11: Qty | AB11: Cum | AC11: Cum | AD11: Cum | AE11: Nos. | AF11: ='[100]Plan- Rohan'!U80 -> 60 | AG11: ='[100]Plan- Rohan'!V80 -> 60 | AH11: ='[100]Plan- Rohan'!W80 -> 20 | AI11: ='[100]Plan- Rohan'!X80 -> 20 | AJ11: ='[100]Plan- Rohan'!Y80 -> 60 | AK11: ='[100]Plan- Rohan'!Z80 -> 220
B12: Qty | D12: =D11*$D$1 -> 6 | E12: =E11*$E$1 -> 40 | F12: =F11*$F$1 -> 10 | G12: =G11*$G$1 -> 12 | H12: =H11*$H$1 -> 20 | J12: =SUM(D12:I12) -> 88 | M12: All qty are in Cum | P12: Cast-in-situ | Q12: Pre-cast | R12: Total | T12: PCC | U12: =D32 -> 69 | V12: =U12*$P$47 -> 33.44856 | Z12: A | AA12: ='[100]Plan- Rohan'!Z56 -> 0 | AB12: ='[100]Plan- Rohan'!Z57 -> 0 | AC12: ='[100]Plan- Rohan'!J8 -> 204 | AD12: =AB12+AC12 -> 204 | AE12: Qty | AF12: ='[100]Plan- Rohan'!U81 -> 720 | AG12: ='[100]Plan- Rohan'!V81 -> 720 | AH12: ='[100]Plan- Rohan'!W81 -> 240 | AI12: ='[100]Plan- Rohan'!X81 -> 240 | AJ12: ='[100]Plan- Rohan'!Y81 -> 30 | AK12: ='[100]Plan- Rohan'!Z81 -> 1950
A13: Part C | B13: Nos. | C13: 4 | D13: 4 | E13: 4 | F13: 4 | G13: 4 | H13: 8 | O13: A | P13: =J8 -> 0 | Q13: ='[100]Precast- Segment Casting plan '!U14 -> 0 | R13: =P13+Q13 -> 0 | T13: RCC Foundation | U13: =E32 -> 460 | V13: =U13*$P$47 -> 222.9904 | Z13: B | AA13: ='[100]Plan- Rohan'!Z58 -> 0 | AB13: ='[100]Plan- Rohan'!Z59 -> 0 | AC13: ='[100]Plan- Rohan'!J10 -> 358 | AD13: =AB13+AC13 -> 358
B14: Qty | D14: =D13*$D$1 -> 12 | E14: =E13*$E$1 -> 80 | F14: =F13*$F$1 -> 20 | G14: =G13*G1 -> 24 | H14: =H13*$H$1 -> 40 | J14: =SUM(D14:I14) -> 176 | O14: B | P14: =J10 -> 310 | Q14: ='[100]Precast- Segment Casting plan '!U15 -> 13.5 | R14: =P14+Q14 -> 323.5 | T14: Step Footing | U14: =F32 -> 115 | V14: =U14*$P$47 -> 55.7476 | Z14: C | AA14: ='[100]Plan- Rohan'!Z62 -> 16 | AB14: ='[100]Plan- Rohan'!Z63 -> 192 | AC14: ='[100]Plan- Rohan'!J14 -> 0 | AD14: =AB14+AC14 -> 192
A15: Part I | B15: Nos. | O15: C | P15: =J14 -> 176 | Q15: ='[100]Precast- Segment Casting plan '!U16 -> 542.5 | R15: =P15+Q15 -> 718.5 | T15: Pier 1900 mm | U15: =G32 -> 222 | V15: =U15*$P$47 -> 107.61711 | Z15: D | AA15: ='[100]Plan- Rohan'!Z66 -> 0 | AB15: ='[100]Plan- Rohan'!Z67 -> 0 | AC15: ='[100]Plan- Rohan'!J18 -> 0 | AD15: =AB15+AC15 -> 0
B16: Qty | D16: =D15*$D$1 -> 0 | E16: =E15*$E$1 -> 0 | F16: =F15*$F$1 -> 0 | H16: =H15*$H$1 -> 0 | J16: =SUM(D16:I16) -> 0 | O16: D | P16: =J18 -> 0 | Q16: ='[100]Precast- Segment Casting plan '!U17 -> 0 | R16: =P16+Q16 -> 0 | T16: Pier 1600 mm | U16: =H32 -> 500 | V16: =U16*$P$47 -> 242.38087 | Z16: E | AA16: ='[100]Plan- Rohan'!Z70 -> 0 | AB16: ='[100]Plan- Rohan'!Z71 -> 0 | AC16: ='[100]Plan- Rohan'!J20 -> 0 | AD16: =AB16+AC16 -> 0
A17: Part D | B17: Nos. | O17: E | P17: =J22 -> 0 | Q17: ='[100]Precast- Segment Casting plan '!U18 -> 0 | R17: =P17+Q17 -> 0 | T17: Pier Cap | U17: =I32 -> 560 | V17: =U17*$P$47 -> 271.46657 | Z17: F | AA17: ='[100]Plan- Rohan'!Z72 -> 0 | AB17: ='[100]Plan- Rohan'!Z73 -> 0 | AC17: ='[100]Plan- Rohan'!J22 -> 150 | AD17: =AB17+AC17 -> 150
B18: Qty | D18: =D17*$D$1 -> 0 | E18: =E17*$E$1 -> 0 | F18: =F17*$F$1 -> 0 | G18: =G17*$G$1 -> 0 | H18: =H17*$H$1 -> 0 | I18: =I17*20 -> 0 | J18: =SUM(D18:I18) -> 0 | O18: F | P18: =J24 -> 0 | Q18: ='[100]Precast- Segment Casting plan '!U19 -> 6.5 | R18: =P18+Q18 -> 6.5 | T18: Track Beam with Nose | U18: =O5 -> 996 | V18: =U18*$P$47 -> 482.82269 | Z18: G | AA18: ='[100]Plan- Rohan'!Z74 -> 159 | AB18: ='[100]Plan- Rohan'!Z75 -> 1218 | AC18: ='[100]Plan- Rohan'!J24 -> 452 | AD18: =AB18+AC18 -> 1670
A19: Priority Section-2 | B19: Nos. | C19: =C21+C23+C25+C27+C29 -> 10 | D19: =D21+D23+D25+D27+D29 -> 15 | E19: =E21+E23+E25+E27+E29 -> 15 | F19: =F21+F23+F25+F27+F29 -> 15 | G19: =G21+G23+G25+G27+G29 -> 27 | H19: =H21+H23+H25+H27+H29 -> 74 | I19: =I21+I23+I25+I27+I29 -> 8 | O19: G | P19: =J26 -> 510 | Q19: ='[100]Precast- Segment Casting plan '!U20 -> 12 | R19: =P19+Q19 -> 522 | T19: Track Beam without Nose | U19: =O6 -> 408 | V19: =U19*$P$47 -> 197.78279 | Z19: H | AA19: ='[100]Plan- Rohan'!Z60 -> 5 | AB19: ='[100]Plan- Rohan'!Z61 -> 60 | AC19: ='[100]Plan- Rohan'!J12 -> 68 | AD19: =AB19+AC19 -> 128
B20: Qty | C20: =C22+C24+C26+C28+C30 -> 0 | D20: =D22+D24+D26+D28+D30 -> 45 | E20: =E22+E24+E26+E28+E30 -> 300 | F20: =F22+F24+F26+F28+F30 -> 75 | G20: =G22+G24+G26+G28+G30 -> 162 | H20: =H22+H24+H26+H28+H30 -> 370 | I20: =I22+I24+I26+I28+I30 -> 400 | J20: =SUM(C20:I20) -> 1352 | O20: H | P20: =J12 -> 88 | Q20: ='[100]Precast- Segment Casting plan '!U21 -> 264 | R20: =P20+Q20 -> 352 | T20: H - Section Beam | U20: =O7 -> 420 | V20: =U20*$P$47 -> 203.59993 | Z20: I | AA20: ='[100]Plan- Rohan'!Z64 -> 40 | AB20: ='[100]Plan- Rohan'!Z65 -> 480 | AC20: ='[100]Plan- Rohan'!J16 -> 0 | AD20: =AB20+AC20 -> 480
A21: Part E | B21: Nos. | O21: I | P21: =J16 -> 0 | Q21: ='[100]Precast- Segment Casting plan '!U22 -> 261.5 | R21: =P21+Q21 -> 261.5 | T21: U - Section Beam | U21: =O8 -> 276 | V21: =U21*$P$47 -> 133.79424 | Z21: J | AA21: ='[100]Plan- Rohan'!Z76 -> 0 | AB21: ='[100]Plan- Rohan'!Z77 -> 0 | AC21: ='[100]Plan- Rohan'!J26 -> 278 | AD21: =AB21+AC21 -> 278
B22: Qty | D22: =D21*$D$1 -> 0 | E22: =E21*$E$1 -> 0 | F22: =F21*$F$1 -> 0 | G22: =G21*$G$1 -> 0 | H22: =H21*$H$1 -> 0 | I22: =I21*$I$1 -> 0 | J22: =SUM(D22:I22) -> 0 | O22: J | P22: =J28 -> 300 | Q22: ='[100]Precast- Segment Casting plan '!U23 -> 324 | R22: =P22+Q22 -> 624 | T22: Pre-cast Slab | U22: =O9 -> 20 | V22: =U22*$P$47 -> 9.6952348 | Z22: K | AA22: ='[100]Plan- Rohan'!Z78 -> 0 | AB22: ='[100]Plan- Rohan'!Z79 -> 0 | AC22: ='[100]Plan- Rohan'!J28 -> 594 | AD22: =AB22+AC22 -> 594
A23: Part F | B23: Nos. | O23: K | P23: =J30 -> 542 | Q23: ='[100]Precast- Segment Casting plan '!U24 -> 696 | R23: =P23+Q23 -> 1238 | T23: Abutment wall- PART-A | U23: =J33 -> 90 | V23: =U23*$P$47 -> 43.628556 | Z23: Abutment wall- PART-A | AC23: ='[100]Plan- Rohan'!J29 -> 84 | AD23: =AB23+AC23 -> 84
B24: Qty | D24: =D23*$D$1 -> 0 | E24: =E23*$E$1 -> 0 | F24: =F23*$F$1 -> 0 | G24: =G23*$G$1 -> 0 | H24: =H23*$H$1 -> 0 | J24: =SUM(D24:I24) -> 0 | O24: Abutment wall- PART-A | P24: =J33 -> 90 | R24: =P24+Q24 -> 90 | T24: Abutment wall- PART-D | U24: =J34 -> 120 | V24: =U24*$P$47 -> 58.171409 | Z24: Abutment wall- PART-D | AC24: ='[100]Plan- Rohan'!J30 -> 500 | AD24: =AB24+AC24 -> 500
A25: Part G | B25: Nos. | C25: 10 | D25: 15 | E25: 15 | F25: 15 | G25: 15 | O25: Abutment wall- PART-D | P25: =J34 -> 120 | R25: =P25+Q25 -> 120 | T25: Cast In-situ slab- 1- PART-G | U25: =J35 -> 0 | V25: =U25*$P$47 -> 0 | Z25: Cast In-situ slab- 1- PART-G | AD25: =AB25+AC25 -> 0
B26: Qty | D26: =D25*$D$1 -> 45 | E26: =E25*$E$1 -> 300 | F26: =F25*$F$1 -> 75 | G26: =G25*$G$1 -> 90 | H26: =H25*$H$1 -> 0 | J26: =SUM(D26:I26) -> 510 | O26: Cast In-situ slab- 1- PART-G | P26: =J35 -> 0 | R26: =P26+Q26 -> 0 | T26: Cast In-situ slab- 2- PART-G | U26: =J36 -> 529 | V26: =U26*$P$47 -> 256.43896 | Z26: Cast In-situ slab- 2- PART-G | AD26: =AB26+AC26 -> 0
A27: Part J | B27: Nos. | I27: 6 | O27: Cast In-situ slab- 2- PART-G | P27: =J36 -> 529 | R27: =P27+Q27 -> 529 | T27: Cast In-situ slab- PART-C | U27: =J37 -> 0 | V27: =U27*$P$47 -> 0 | Z27: Cast In-situ slab- PART-C | AD27: =AB27+AC27 -> 0
B28: Qty | D28: =D27*$D$1 -> 0 | E28: =E27*$E$1 -> 0 | F28: =F27*$F$1 -> 0 | G28: =G27*$G$1 -> 0 | H28: =H27*$H$1 -> 0 | I28: =I27*50 -> 300 | J28: =SUM(D28:I28) -> 300 | O28: Cast In-situ slab- PART-C | P28: =J37 -> 0 | R28: =P28+Q28 -> 0 | U28: =SUM(U12:U27) -> 4785 | V28: =U28*$P$47 -> 2319.5849 | AA28: =SUM(AA12:AA27) -> 220 | AB28: =SUM(AB12:AB27) -> 1950 | AC28: =SUM(AC12:AC27) -> 2688 | AD28: =SUM(AD12:AD27) -> 4638
A29: Part K | B29: Nos. | G29: 12 | H29: 74 | I29: 2 | P29: =SUM(P13:P28) -> 2665 | Q29: =SUM(Q13:Q28) -> 2120 | R29: =SUM(R13:R28) -> 4785
B30: Qty | D30: =D29*$D$1 -> 0 | E30: =E29*$E$1 -> 0 | F30: =F29*$F$1 -> 0 | G30: =G29*$G$1 -> 72 | H30: =H29*$H$1 -> 370 | I30: =I29*50 -> 100 | J30: =SUM(D30:I30) -> 542
A31: Total | B31: Nos. | D31: =D30*$D$1 -> 0 | E31: =E30*$E$1 -> 0 | F31: =F30*$F$1 -> 0 | G31: =G30*$G$1 -> 432 | H31: =H30*$H$1 -> 1850 | I31: =I30*40 -> 4000 | J31: =SUM(D31:I31) -> 6282
B32: Qty | C32: =C6+C20 -> 0 | D32: =D6+D20 -> 69 | E32: =E6+E20 -> 460 | F32: =F6+F20 -> 115 | G32: =G6+G20 -> 222 | H32: =H6+H20 -> 500 | I32: =I6+I20 -> 560 | J32: =SUM(C32:I32) -> 1926
A33: Abutment wall- PART-A | D33: 10 | E33: 80 | J33: =SUM(C33:I33) -> 90
A34: Abutment wall- PART-D | E34: 120 | J34: =SUM(C34:I34) -> 120
A35: Cast In-situ slab- 1- PART-G | J35: =SUM(C35:I35) -> 0
A36: Cast In-situ slab- 2- PART-G | E36: 529 | J36: =SUM(C36:I36) -> 529
A37: Cast In-situ slab- PART-C
A38: Cast Insitu | J38: =SUM(C38:I38) -> 0
J39: =SUM(J32:J38) -> 2665
J40: Pre-cast | K40: Week-wise Planned
...

Sheet Top Sheet
B3: Project: 5 MTPA Integrated Steel Plant at Vijayanagar
B4: ELEVATED HOT METAL TRACK
B6: Client Name: JVML | G6: REPORT DATE | H6: 45278 | I6: WEATHER : | J6: Sunny
B7: PMC: KPMG | AB7: Engineering Progress
B8: Contractor: Rohan Builder India Pvt Ltd | G8: REPORTING DATE | H8: =H6+1 -> 45279 | I8: WORKING : | J8: Full day
B9: OVERALL PHYSICAL PROGRESS
C10: Month | D10: 45261 | AJ10: Actuals for the month
W11: =EOMONTH('Top Sheet'!D10,0) -> 45291 | X11: =EDATE(D10,0) -> 45261 | Y11: =H6 -> 45278 | Z11: =W11-Y11 -> 13 | AI11: Areas | AJ11: PCC | AK11: RCC Foundation | AL11: Step Footing | AM11: Pier 1900 mm | AN11: Pier 1600 mm | AO11: Pier Cap | AP11: Track Beam with Nose | AQ11: Track Beam without Nose | AR11: h - Section Beam | AS11: U - Section Beam | AT11: Pre-cast Slab | AU11: Erection-Track Beam with Nose | AV11: Erection-Track Beam without Nose | AW11: Erection-h - Section Beam | AX11: Erection-U - Section Beam | AY11: Erection-Pre-cast Slab | AZ11: Track Laying
W12: Month | X12: 45261 | AB12: Item Description | AC12: UOM | AD12: Scope (cum) | AE12: Completed Till date (cum) | AF12: % Complete | AG12: Scope (nos.) | AH12: Completed Till date (nos.) | AI12: A | AJ12: =SUMIFS(Backup!$K:$K,Backup!$D:$D,Details!$B$8,Backup!$B:$B,AI12,Backup!$A:$A,"<="&'Top Sheet'!$W$11,Backup!$A:$A,">="&$X$11) -> 0 | AK12: =SUMIFS(Backup!$M:$M,Backup!$D:$D,Details!$B$9,Backup!$B:$B,AI12,Backup!$A:$A,"<="&'Top Sheet'!$W$11,Backup!$A:$A,">="&$X$11) -> 0 | AL12: =SUMIFS(Backup!$M:$M,Backup!$D:$D,Details!$B$10,Backup!$B:$B,AI12,Backup!$A:$A,"<="&'Top Sheet'!$W$11,Backup!$A:$A,">="&$X$11) -> 0 | AM12: =SUMIFS(Backup!$M:$M,Backup!$D:$D,Details!$B$11,Backup!$B:$B,AI12,Backup!$A:$A,"<="&'Top Sheet'!$W$11,Backup!$A:$A,">="&$X$11) -> 0 | AN12: =SUMIFS(Backup!$M:$M,Backup!$D:$D,Details!$B$12,Backup!$B:$B,AI12,Backup!$A:$A,"<="&'Top Sheet'!$W$11,Backup!$A:$A,">="&$X$11) -> 0 | AO12: =SUMIFS(Backup!$N:$N,Backup!$D:$D,Details!$B$13,Backup!$B:$B,AI12,Backup!$A:$A,"<="&'Top Sheet'!$W$11,Backup!$A:$A,">="&$X$11) -> 0 | AP12: =SUMIFS(Backup!$N:$N,Backup!$D:$D,Details!$B$14,Backup!$B:$B,AI12,Backup!$A:$A,"<="&'Top Sheet'!$W$11,Backup!$A:$A,">="&$X$11) -> 0 | AQ12: =SUMIFS(Backup!$N:$N,Backup!$D:$D,Details!$B$15,Backup!$B:$B,AI12,Backup!$A:$A,"<="&'Top Sheet'!$W$11,Backup!$A:$A,">="&$X$11) -> 0 | AR12: =SUMIFS(Backup!$N:$N,Backup!$D:$D,Details!$B$16,Backup!$B:$B,AI12,Backup!$A:$A,"<="&'Top Sheet'!$W$11,Backup!$A:$A,">="&$X$11) -> 0 | AS12: =SUMIFS(Backup!$N:$N,Backup!$D:$D,Details!$B$17,Backup!$B:$B,AI12,Backup!$A:$A,"<="&'Top Sheet'!$W$11,Backup!$A:$A,">="&$X$11) -> 0 | AT12: =SUMIFS(Backup!$N:$N,Backup!$D:$D,Details!$B$18,Backup!$B:$B,AI12,Backup!$A:$A,"<="&'Top Sheet'!$W$11,Backup!$A:$A,">="&$X$11) -> 2.5 | AU12: =SUMIFS(Backup!$N:$N,Backup!$D:$D,Details!$B$19,Backup!$B:$B,AI12,Backup!$A:$A,"<="&'Top Sheet'!$W$11,Backup!$A:$A,">="&$X$11) -> 0 | AV12: =SUMIFS(Backup!$N:$N,Backup!$D:$D,Details!$B$20,Backup!$B:$B,AI12,Backup!$A:$A,"<="&'Top Sheet'!$W$11,Backup!$A:$A,">="&$X$11) -> 0 | AW12: =SUMIFS(Backup!$N:$N,Backup!$D:$D,Details!$B$21,Backup!$B:$B,AI12,Backup!$A:$A,"<="&'Top Sheet'!$W$11,Backup!$A:$A,">="&$X$11) -> 0 | AX12: =SUMIFS(Backup!$N:$N,Backup!$D:$D,Details!$B$22,Backup!$B:$B,AI12,Backup!$A:$A,"<="&'Top Sheet'!$W$11,Backup!$A:$A,">="&$X$11) -> 0 | AY12: =SUMIFS(Backup!$N:$N,Backup!$D:$D,Details!$B$23,Backup!$B:$B,AI12,Backup!$A:$A,"<="&'Top Sheet'!$W$11,Backup!$A:$A,">="&$X$11) -> 0 | AZ12: =SUMIFS(Backup!$K:$K,Backup!$D:$D,Details!$B$24,Backup!$B:$B,AI12,Backup!$A:$A,"<="&'Top Sheet'!$W$11,Backup!$A:$A,">="&$X$11) -> 0 | BA12: =SUMIFS(Backup!$K:$K,Backup!$D:$D,Details!$B$8,Backup!$B:$B,$AI$12,Backup!$B:$B,"<="&'Top Sheet'!$W$11,Backup!$B:$B,">="&$X$11) -> 0
U13: Daily Actual | V13: Month Actual | W13: Item Description | X13: Month Plan | Y13: Month Actual | Z13: Plan in Nos | AB13: PCC | AC13: CuM | AD13: 2033.9804 | AE13: =SUMIFS(Backup!$P:$P,Backup!$D:$D,'Top Sheet'!$AB13) -> 1840 | AF13: =AE13/AD13 -> 0.90463016 | AG13: =AD13/'Civil S-curve'!$D2 -> 581.13725 | AH13: =AE13/'Civil S-curve'!$D2 -> 525.71429 | AI13: B | AJ13: =SUMIFS(Backup!$K:$K,Backup!$D:$D,Details!$B$8,Backup!$B:$B,AI13,Backup!$A:$A,"<="&'Top Sheet'!$W$11,Backup!$A:$A,">="&$X$11) -> 10 | AK13: =SUMIFS(Backup!$M:$M,Backup!$D:$D,Details!$B$9,Backup!$B:$B,AI13,Backup!$A:$A,"<="&'Top Sheet'!$W$11,Backup!$A:$A,">="&$X$11) -> 0 | AL13: =SUMIFS(Backup!$M:$M,Backup!$D:$D,Details!$B$10,Backup!$B:$B,AI13,Backup!$A:$A,"<="&'Top Sheet'!$W$11,Backup!$A:$A,">="&$X$11) -> 0 | AM13: =SUMIFS(Backup!$M:$M,Backup!$D:$D,Details!$B$11,Backup!$B:$B,AI13,Backup!$A:$A,"<="&'Top Sheet'!$W$11,Backup!$A:$A,">="&$X$11) -> 0 | AN13: =SUMIFS(Backup!$M:$M,Backup!$D:$D,Details!$B$12,Backup!$B:$B,AI13,Backup!$A:$A,"<="&'Top Sheet'!$W$11,Backup!$A:$A,">="&$X$11) -> 0 | AO13: =SUMIFS(Backup!$N:$N,Backup!$D:$D,Details!$B$13,Backup!$B:$B,AI13,Backup!$A:$A,"<="&'Top Sheet'!$W$11,Backup!$A:$A,">="&$X$11) -> 64 | AP13: =SUMIFS(Backup!$N:$N,Backup!$D:$D,Details!$B$14,Backup!$B:$B,AI13,Backup!$A:$A,"<="&'Top Sheet'!$W$11,Backup!$A:$A,">="&$X$11) -> 0 | AQ13: =SUMIFS(Backup!$N:$N,Backup!$D:$D,Details!$B$15,Backup!$B:$B,AI13,Backup!$A:$A,"<="&'Top Sheet'!$W$11,Backup!$A:$A,">="&$X$11) -> 0 | AR13: =SUMIFS(Backup!$N:$N,Backup!$D:$D,Details!$B$16,Backup!$B:$B,AI13,Backup!$A:$A,"<="&'Top Sheet'!$W$11,Backup!$A:$A,">="&$X$11) -> 36 | AS13: =SUMIFS(Backup!$N:$N,Backup!$D:$D,Details!$B$17,Backup!$B:$B,AI13,Backup!$A:$A,"<="&'Top Sheet'!$W$11,Backup!$A:$A,">="&$X$11) -> 0 | AT13: =SUMIFS(Backup!$N:$N,Backup!$D:$D,Details!$B$18,Backup!$B:$B,AI13,Backup!$A:$A,"<="&'Top Sheet'!$W$11,Backup!$A:$A,">="&$X$11) -> 0 | AU13: =SUMIFS(Backup!$N:$N,Backup!$D:$D,Details!$B$19,Backup!$B:$B,AI13,Backup!$A:$A,"<="&'Top Sheet'!$W$11,Backup!$A:$A,">="&$X$11) -> 0 | AV13: =SUMIFS(Backup!$N:$N,Backup!$D:$D,Details!$B$20,Backup!$B:$B,AI13,Backup!$A:$A,"<="&'Top Sheet'!$W$11,Backup!$A:$A,">="&$X$11) -> 0 | AW13: =SUMIFS(Backup!$N:$N,Backup!$D:$D,Details!$B$21,Backup!$B:$B,AI13,Backup!$A:$A,"<="&'Top Sheet'!$W$11,Backup!$A:$A,">="&$X$11) -> 0 | AX13: =SUMIFS(Backup!$N:$N,Backup!$D:$D,Details!$B$22,Backup!$B:$B,AI13,Backup!$A:$A,"<="&'Top Sheet'!$W$11,Backup!$A:$A,">="&$X$11) -> 0 | AY13: =SUMIFS(Backup!$N:$N,Backup!$D:$D,Details!$B$23,Backup!$B:$B,AI13,Backup!$A:$A,"<="&'Top Sheet'!$W$11,Backup!$A:$A,">="&$X$11) -> 0 | AZ13: =SUMIFS(Backup!$K:$K,Backup!$D:$D,Details!$B$24,Backup!$B:$B,AI13,Backup!$A:$A,"<="&'Top Sheet'!$W$11,Backup!$A:$A,">="&$X$11) -> 0 | BA13: =SUMIFS(Backup!$K:$K,Backup!$D:$D,Details!$B$9,Backup!$B:$B,$AI$13,Backup!$B:$B,"<="&'Top Sheet'!$W$11,Backup!$B:$B,">="&$X$11) -> 0
U14: =SUMIFS(Backup!$P:$P,Backup!$D:$D,W14, Backup!$A:$A,$H$6) -> 28 | V14: =SUMIFS(Backup!$P:$P,Backup!$D:$D,'Top Sheet'!$W14,Backup!$A:$A,"<="&'Top Sheet'!$W$11,Backup!$A:$A,">="&'Top Sheet'!$X$11) -> 109 | W14: PCC | X14: =SUMIFS('Month-wise Plan'!$E3:$AA3,'Month-wise Plan'!$E$2:$AA$2,'Top Sheet'!$D$10) -> 0 | Y14: =SUMIFS(Backup!$K:$K,Backup!$D:$D,'Top Sheet'!$W14,Backup!$A:$A,"<="&'Top Sheet'!$W$11,Backup!$A:$A,">="&'Top Sheet'!$X$11) -> 109 | Z14: =SUMIFS('Month-wise Plan'!$E$28:$AA$28,'Month-wise Plan'!$E$2:$AA$2,'Top Sheet'!$D$10) -> 0 | AB14: RCC Foundation | AC14: CuM | AD14: 13947.294 | AE14: =SUMIFS(Backup!$P:$P,Backup!$D:$D,'Top Sheet'!$AB14) -> 11022.75 | AF14: =AE14/AD14 -> 0.79031459 | AG14: =AD14/'Civil S-curve'!$D3 -> 581.13725 | AH14: =AE14/'Civil S-curve'!$D3 -> 459.28125 | AI14: C | AJ14: =SUMIFS(Backup!$K:$K,Backup!$D:$D,Details!$B$8,Backup!$B:$B,AI14,Backup!$A:$A,"<="&'Top Sheet'!$W$11,Backup!$A:$A,">="&$X$11) -> 0 | AK14: =SUMIFS(Backup!$M:$M,Backup!$D:$D,Details!$B$9,Backup!$B:$B,AI14,Backup!$A:$A,"<="&'Top Sheet'!$W$11,Backup!$A:$A,">="&$X$11) -> 0 | AL14: =SUMIFS(Backup!$M:$M,Backup!$D:$D,Details!$B$10,Backup!$B:$B,AI14,Backup!$A:$A,"<="&'Top Sheet'!$W$11,Backup!$A:$A,">="&$X$11) -> 0 | AM14: =SUMIFS(Backup!$M:$M,Backup!$D:$D,Details!$B$11,Backup!$B:$B,AI14,Backup!$A:$A,"<="&'Top Sheet'!$W$11,Backup!$A:$A,">="&$X$11) -> 0 | AN14: =SUMIFS(Backup!$M:$M,Backup!$D:$D,Details!$B$12,Backup!$B:$B,AI14,Backup!$A:$A,"<="&'Top Sheet'!$W$11,Backup!$A:$A,">="&$X$11) -> 0 | AO14: =SUMIFS(Backup!$N:$N,Backup!$D:$D,Details!$B$13,Backup!$B:$B,AI14,Backup!$A:$A,"<="&'Top Sheet'!$W$11,Backup!$A:$A,">="&$X$11) -> 0 | AP14: =SUMIFS(Backup!$N:$N,Backup!$D:$D,Details!$B$14,Backup!$B:$B,AI14,Backup!$A:$A,"<="&'Top Sheet'!$W$11,Backup!$A:$A,">="&$X$11) -> 0 | AQ14: =SUMIFS(Backup!$N:$N,Backup!$D:$D,Details!$B$15,Backup!$B:$B,AI14,Backup!$A:$A,"<="&'Top Sheet'!$W$11,Backup!$A:$A,">="&$X$11) -> 0 | AR14: =SUMIFS(Backup!$N:$N,Backup!$D:$D,Details!$B$16,Backup!$B:$B,AI14,Backup!$A:$A,"<="&'Top Sheet'!$W$11,Backup!$A:$A,">="&$X$11) -> 72 | AS14: =SUMIFS(Backup!$N:$N,Backup!$D:$D,Details!$B$17,Backup!$B:$B,AI14,Backup!$A:$A,"<="&'Top Sheet'!$W$11,Backup!$A:$A,">="&$X$11) -> 0 | AT14: =SUMIFS(Backup!$N:$N,Backup!$D:$D,Details!$B$18,Backup!$B:$B,AI14,Backup!$A:$A,"<="&'Top Sheet'!$W$11,Backup!$A:$A,">="&$X$11) -> 0 | AU14: =SUMIFS(Backup!$N:$N,Backup!$D:$D,Details!$B$19,Backup!$B:$B,AI14,Backup!$A:$A,"<="&'Top Sheet'!$W$11,Backup!$A:$A,">="&$X$11) -> 0 | AV14: =SUMIFS(Backup!$N:$N,Backup!$D:$D,Details!$B$20,Backup!$B:$B,AI14,Backup!$A:$A,"<="&'Top Sheet'!$W$11,Backup!$A:$A,">="&$X$11) -> 0 | AW14: =SUMIFS(Backup!$N:$N,Backup!$D:$D,Details!$B$21,Backup!$B:$B,AI14,Backup!$A:$A,"<="&'Top Sheet'!$W$11,Backup!$A:$A,">="&$X$11) -> 0 | AX14: =SUMIFS(Backup!$N:$N,Backup!$D:$D,Details!$B$22,Backup!$B:$B,AI14,Backup!$A:$A,"<="&'Top Sheet'!$W$11,Backup!$A:$A,">="&$X$11) -> 0 | AY14: =SUMIFS(Backup!$N:$N,Backup!$D:$D,Details!$B$23,Backup!$B:$B,AI14,Backup!$A:$A,"<="&'Top Sheet'!$W$11,Backup!$A:$A,">="&$X$11) -> 0 | AZ14: =SUMIFS(Backup!$K:$K,Backup!$D:$D,Details!$B$24,Backup!$B:$B,AI14,Backup!$A:$A,"<="&'Top Sheet'!$W$11,Backup!$A:$A,">="&$X$11) -> 0 | BA14: =SUMIFS(Backup!$K:$K,Backup!$D:$D,Details!$B$10,Backup!$B:$B,$AI$14,Backup!$B:$B,"<="&'Top Sheet'!$W$11,Backup!$B:$B,">="&$X$11) -> 0
